<?xml version="1.0" ?>
<sdf version="1.8">
  <model name="amr_robot">
    <pose>0 0 0.15 0 0 0</pose>

    <link name="base_link">
      <inertial><mass>10.0</mass><inertia><ixx>0.1</ixx><iyy>0.1</iyy><izz>0.1</izz></inertia></inertial>
      <collision name="base_collision"><geometry><box><size>0.4 0.3 0.1</size></box></geometry></collision>
      <visual name="base_visual"><geometry><box><size>0.4 0.3 0.1</size></box></geometry></visual>
    </link>

    <link name="left_wheel">
      <pose>0 0.15 0.05 0 0 0</pose>
      <collision name="left_collision">
        <pose>0 0 0 1.5708 0 0</pose>
        <geometry><cylinder><radius>0.05</radius><length>0.02</length></cylinder></geometry>
        <surface><friction><ode><mu>2.0</mu><mu2>2.0</mu2></ode></friction></surface>
      </collision>
      <visual name="left_visual"><pose>0 0 0 1.5708 0 0</pose><geometry><cylinder><radius>0.05</radius><length>0.02</length></cylinder></geometry></visual>
    </link>

    <link name="right_wheel">
      <pose>0 -0.15 0.05 0 0 0</pose>
      <collision name="right_collision">
        <pose>0 0 0 1.5708 0 0</pose>
        <geometry><cylinder><radius>0.05</radius><length>0.02</length></cylinder></geometry>
        <surface><friction><ode><mu>2.0</mu><mu2>2.0</mu2></ode></friction></surface>
      </collision>
      <visual name="right_visual"><pose>0 0 0 1.5708 0 0</pose><geometry><cylinder><radius>0.05</radius><length>0.02</length></cylinder></geometry></visual>
    </link>

    <joint name="left_wheel_joint" type="revolute"><parent>base_link</parent><child>left_wheel</child><axis><xyz>0 0 1</xyz></axis></joint>
    <joint name="right_wheel_joint" type="revolute"><parent>base_link</parent><child>right_wheel</child><axis><xyz>0 0 1</xyz></axis></joint>

    <link name="rear_caster">
      <pose>-0.15 0 -0.07 0 0 0</pose>
      <collision name="caster_collision"><geometry><sphere><radius>0.03</radius></sphere></geometry></collision>
      <visual name="caster_visual"><geometry><sphere><radius>0.03</radius></sphere></geometry></visual>
    </link>
    <joint name="caster_joint" type="ball"><parent>base_link</parent><child>rear_caster</child></joint>

    <link name="lidar_link">
      <pose>0.15 0 0.05 0 0 0</pose>
      <visual name="lidar_visual"><geometry><cylinder><radius>0.04</radius><length>0.05</length></cylinder></geometry></visual>
      <sensor name="lidar_sensor" type="gpu_lidar">
        <topic>/scan</topic>
        <update_rate>10</update_rate>
        <lidar><scan><horizontal><samples>720</samples><min_angle>-3.14</min_angle><max_angle>3.14</max_angle></horizontal></scan><range><min>0.1</min><max>10.0</max></range></lidar>
      </sensor>
    </link>
    <joint name="lidar_joint" type="fixed"><parent>base_link</parent><child>lidar_link</child></joint>

    <plugin filename="libignition-gazebo-diff-drive-system.so" name="ignition::gazebo::systems::DiffDrive">
      <left_joint>left_wheel_joint</left_joint><right_joint>right_wheel_joint</right_joint>
      <wheel_separation>0.30</wheel_separation><wheel_radius>0.05</wheel_radius><topic>/cmd_vel</topic>
    </plugin>
  </model>
</sdf>
